[2025-03-28T16:19:46.568+0000] {local_task_job_runner.py:123} INFO - ::group::Pre task execution logs
[2025-03-28T16:19:46.603+0000] {taskinstance.py:2614} INFO - Dependencies all met for dep_context=non-requeueable deps ti=<TaskInstance: nasa_data_pipeline.load_to_postgres manual__2025-03-28T16:19:11.887477+00:00 [queued]>
[2025-03-28T16:19:46.617+0000] {taskinstance.py:2614} INFO - Dependencies all met for dep_context=requeueable deps ti=<TaskInstance: nasa_data_pipeline.load_to_postgres manual__2025-03-28T16:19:11.887477+00:00 [queued]>
[2025-03-28T16:19:46.619+0000] {taskinstance.py:2867} INFO - Starting attempt 1 of 1
[2025-03-28T16:19:46.859+0000] {taskinstance.py:2890} INFO - Executing <Task(BashOperator): load_to_postgres> on 2025-03-28 16:19:11.887477+00:00
[2025-03-28T16:19:46.872+0000] {standard_task_runner.py:104} INFO - Running: ['***', 'tasks', 'run', 'nasa_data_pipeline', 'load_to_postgres', 'manual__2025-03-28T16:19:11.887477+00:00', '--job-id', '173', '--raw', '--subdir', 'DAGS_FOLDER/nasa_data_pipeline.py', '--cfg-path', '/tmp/tmpjbd_1916']
[2025-03-28T16:19:46.880+0000] {standard_task_runner.py:105} INFO - Job 173: Subtask load_to_postgres
[2025-03-28T16:19:46.879+0000] {warnings.py:112} WARNING - /home/***/.local/lib/python3.12/site-packages/***/task/task_runner/standard_task_runner.py:70: DeprecationWarning: This process (pid=149) is multi-threaded, use of fork() may lead to deadlocks in the child.
  pid = os.fork()

[2025-03-28T16:19:46.884+0000] {standard_task_runner.py:72} INFO - Started process 151 to run task
[2025-03-28T16:19:46.990+0000] {task_command.py:467} INFO - Running <TaskInstance: nasa_data_pipeline.load_to_postgres manual__2025-03-28T16:19:11.887477+00:00 [running]> on host 0b56b63854fa
[2025-03-28T16:19:47.149+0000] {taskinstance.py:3134} INFO - Exporting env vars: AIRFLOW_CTX_DAG_OWNER='***' AIRFLOW_CTX_DAG_ID='nasa_data_pipeline' AIRFLOW_CTX_TASK_ID='load_to_postgres' AIRFLOW_CTX_EXECUTION_DATE='2025-03-28T16:19:11.887477+00:00' AIRFLOW_CTX_TRY_NUMBER='1' AIRFLOW_CTX_DAG_RUN_ID='manual__2025-03-28T16:19:11.887477+00:00'
[2025-03-28T16:19:47.150+0000] {logging_mixin.py:190} INFO - Task instance is in running state
[2025-03-28T16:19:47.151+0000] {logging_mixin.py:190} INFO -  Previous state of the Task instance: queued
[2025-03-28T16:19:47.152+0000] {logging_mixin.py:190} INFO - Current task name:load_to_postgres state:running start_date:2025-03-28 16:19:46.604629+00:00
[2025-03-28T16:19:47.152+0000] {logging_mixin.py:190} INFO - Dag name:nasa_data_pipeline and current dag run status:running
[2025-03-28T16:19:47.153+0000] {taskinstance.py:732} INFO - ::endgroup::
[2025-03-28T16:19:47.154+0000] {subprocess.py:78} INFO - Tmp dir root location: /tmp
[2025-03-28T16:19:47.156+0000] {subprocess.py:88} INFO - Running command: ['/usr/bin/bash', '-c', 'python /opt/***/scripts/load_to_postgres.py']
[2025-03-28T16:19:47.182+0000] {subprocess.py:99} INFO - Output:
[2025-03-28T16:19:49.709+0000] {subprocess.py:106} INFO - Traceback (most recent call last):
[2025-03-28T16:19:49.711+0000] {subprocess.py:106} INFO -   File "/home/***/.local/lib/python3.12/site-packages/sqlalchemy/engine/base.py", line 3371, in _wrap_pool_connect
[2025-03-28T16:19:49.712+0000] {subprocess.py:106} INFO -     return fn()
[2025-03-28T16:19:49.713+0000] {subprocess.py:106} INFO -            ^^^^
[2025-03-28T16:19:49.714+0000] {subprocess.py:106} INFO -   File "/home/***/.local/lib/python3.12/site-packages/sqlalchemy/pool/base.py", line 327, in connect
[2025-03-28T16:19:49.715+0000] {subprocess.py:106} INFO -     return _ConnectionFairy._checkout(self)
[2025-03-28T16:19:49.716+0000] {subprocess.py:106} INFO -            ^^^^^^^^^^^^^^^^^^^^^^^^^^^^^^^^
[2025-03-28T16:19:49.716+0000] {subprocess.py:106} INFO -   File "/home/***/.local/lib/python3.12/site-packages/sqlalchemy/pool/base.py", line 894, in _checkout
[2025-03-28T16:19:49.717+0000] {subprocess.py:106} INFO -     fairy = _ConnectionRecord.checkout(pool)
[2025-03-28T16:19:49.718+0000] {subprocess.py:106} INFO -             ^^^^^^^^^^^^^^^^^^^^^^^^^^^^^^^^
[2025-03-28T16:19:49.719+0000] {subprocess.py:106} INFO -   File "/home/***/.local/lib/python3.12/site-packages/sqlalchemy/pool/base.py", line 493, in checkout
[2025-03-28T16:19:49.720+0000] {subprocess.py:106} INFO -     rec = pool._do_get()
[2025-03-28T16:19:49.721+0000] {subprocess.py:106} INFO -           ^^^^^^^^^^^^^^
[2025-03-28T16:19:49.722+0000] {subprocess.py:106} INFO -   File "/home/***/.local/lib/python3.12/site-packages/sqlalchemy/pool/impl.py", line 145, in _do_get
[2025-03-28T16:19:49.723+0000] {subprocess.py:106} INFO -     with util.safe_reraise():
[2025-03-28T16:19:49.723+0000] {subprocess.py:106} INFO -          ^^^^^^^^^^^^^^^^^^^
[2025-03-28T16:19:49.724+0000] {subprocess.py:106} INFO -   File "/home/***/.local/lib/python3.12/site-packages/sqlalchemy/util/langhelpers.py", line 70, in __exit__
[2025-03-28T16:19:49.725+0000] {subprocess.py:106} INFO -     compat.raise_(
[2025-03-28T16:19:49.726+0000] {subprocess.py:106} INFO -   File "/home/***/.local/lib/python3.12/site-packages/sqlalchemy/util/compat.py", line 211, in raise_
[2025-03-28T16:19:49.727+0000] {subprocess.py:106} INFO -     raise exception
[2025-03-28T16:19:49.728+0000] {subprocess.py:106} INFO -   File "/home/***/.local/lib/python3.12/site-packages/sqlalchemy/pool/impl.py", line 143, in _do_get
[2025-03-28T16:19:49.728+0000] {subprocess.py:106} INFO -     return self._create_connection()
[2025-03-28T16:19:49.729+0000] {subprocess.py:106} INFO -            ^^^^^^^^^^^^^^^^^^^^^^^^^
[2025-03-28T16:19:49.730+0000] {subprocess.py:106} INFO -   File "/home/***/.local/lib/python3.12/site-packages/sqlalchemy/pool/base.py", line 273, in _create_connection
[2025-03-28T16:19:49.730+0000] {subprocess.py:106} INFO -     return _ConnectionRecord(self)
[2025-03-28T16:19:49.731+0000] {subprocess.py:106} INFO -            ^^^^^^^^^^^^^^^^^^^^^^^
[2025-03-28T16:19:49.732+0000] {subprocess.py:106} INFO -   File "/home/***/.local/lib/python3.12/site-packages/sqlalchemy/pool/base.py", line 388, in __init__
[2025-03-28T16:19:49.732+0000] {subprocess.py:106} INFO -     self.__connect()
[2025-03-28T16:19:49.733+0000] {subprocess.py:106} INFO -   File "/home/***/.local/lib/python3.12/site-packages/sqlalchemy/pool/base.py", line 690, in __connect
[2025-03-28T16:19:49.734+0000] {subprocess.py:106} INFO -     with util.safe_reraise():
[2025-03-28T16:19:49.735+0000] {subprocess.py:106} INFO -          ^^^^^^^^^^^^^^^^^^^
[2025-03-28T16:19:49.735+0000] {subprocess.py:106} INFO -   File "/home/***/.local/lib/python3.12/site-packages/sqlalchemy/util/langhelpers.py", line 70, in __exit__
[2025-03-28T16:19:49.736+0000] {subprocess.py:106} INFO -     compat.raise_(
[2025-03-28T16:19:49.737+0000] {subprocess.py:106} INFO -   File "/home/***/.local/lib/python3.12/site-packages/sqlalchemy/util/compat.py", line 211, in raise_
[2025-03-28T16:19:49.738+0000] {subprocess.py:106} INFO -     raise exception
[2025-03-28T16:19:49.739+0000] {subprocess.py:106} INFO -   File "/home/***/.local/lib/python3.12/site-packages/sqlalchemy/pool/base.py", line 686, in __connect
[2025-03-28T16:19:49.740+0000] {subprocess.py:106} INFO -     self.dbapi_connection = connection = pool._invoke_creator(self)
[2025-03-28T16:19:49.741+0000] {subprocess.py:106} INFO -                                          ^^^^^^^^^^^^^^^^^^^^^^^^^^
[2025-03-28T16:19:49.743+0000] {subprocess.py:106} INFO -   File "/home/***/.local/lib/python3.12/site-packages/sqlalchemy/engine/create.py", line 574, in connect
[2025-03-28T16:19:49.744+0000] {subprocess.py:106} INFO -     return dialect.connect(*cargs, **cparams)
[2025-03-28T16:19:49.745+0000] {subprocess.py:106} INFO -            ^^^^^^^^^^^^^^^^^^^^^^^^^^^^^^^^^^
[2025-03-28T16:19:49.746+0000] {subprocess.py:106} INFO -   File "/home/***/.local/lib/python3.12/site-packages/sqlalchemy/engine/default.py", line 598, in connect
[2025-03-28T16:19:49.747+0000] {subprocess.py:106} INFO -     return self.dbapi.connect(*cargs, **cparams)
[2025-03-28T16:19:49.748+0000] {subprocess.py:106} INFO -            ^^^^^^^^^^^^^^^^^^^^^^^^^^^^^^^^^^^^^
[2025-03-28T16:19:49.748+0000] {subprocess.py:106} INFO -   File "/home/***/.local/lib/python3.12/site-packages/psycopg2/__init__.py", line 122, in connect
[2025-03-28T16:19:49.749+0000] {subprocess.py:106} INFO -     conn = _connect(dsn, connection_factory=connection_factory, **kwasync)
[2025-03-28T16:19:49.750+0000] {subprocess.py:106} INFO -            ^^^^^^^^^^^^^^^^^^^^^^^^^^^^^^^^^^^^^^^^^^^^^^^^^^^^^^^^^^^^^^^
[2025-03-28T16:19:49.751+0000] {subprocess.py:106} INFO - psycopg2.OperationalError: connection to server at "localhost" (::1), port 5432 failed: Connection refused
[2025-03-28T16:19:49.752+0000] {subprocess.py:106} INFO - 	Is the server running on that host and accepting TCP/IP connections?
[2025-03-28T16:19:49.753+0000] {subprocess.py:106} INFO - connection to server at "localhost" (127.0.0.1), port 5432 failed: Connection refused
[2025-03-28T16:19:49.753+0000] {subprocess.py:106} INFO - 	Is the server running on that host and accepting TCP/IP connections?
[2025-03-28T16:19:49.754+0000] {subprocess.py:106} INFO - 
[2025-03-28T16:19:49.755+0000] {subprocess.py:106} INFO - 
[2025-03-28T16:19:49.755+0000] {subprocess.py:106} INFO - The above exception was the direct cause of the following exception:
[2025-03-28T16:19:49.756+0000] {subprocess.py:106} INFO - 
[2025-03-28T16:19:49.757+0000] {subprocess.py:106} INFO - Traceback (most recent call last):
[2025-03-28T16:19:49.757+0000] {subprocess.py:106} INFO -   File "/opt/***/scripts/load_to_postgres.py", line 26, in <module>
[2025-03-28T16:19:49.759+0000] {subprocess.py:106} INFO -     with engine.connect() as conn:
[2025-03-28T16:19:49.760+0000] {subprocess.py:106} INFO -          ^^^^^^^^^^^^^^^^
[2025-03-28T16:19:49.761+0000] {subprocess.py:106} INFO -   File "/home/***/.local/lib/python3.12/site-packages/sqlalchemy/engine/base.py", line 3325, in connect
[2025-03-28T16:19:49.762+0000] {subprocess.py:106} INFO -     return self._connection_cls(self, close_with_result=close_with_result)
[2025-03-28T16:19:49.762+0000] {subprocess.py:106} INFO -            ^^^^^^^^^^^^^^^^^^^^^^^^^^^^^^^^^^^^^^^^^^^^^^^^^^^^^^^^^^^^^^^
[2025-03-28T16:19:49.763+0000] {subprocess.py:106} INFO -   File "/home/***/.local/lib/python3.12/site-packages/sqlalchemy/engine/base.py", line 96, in __init__
[2025-03-28T16:19:49.763+0000] {subprocess.py:106} INFO -     else engine.raw_connection()
[2025-03-28T16:19:49.764+0000] {subprocess.py:106} INFO -          ^^^^^^^^^^^^^^^^^^^^^^^
[2025-03-28T16:19:49.765+0000] {subprocess.py:106} INFO -   File "/home/***/.local/lib/python3.12/site-packages/sqlalchemy/engine/base.py", line 3404, in raw_connection
[2025-03-28T16:19:49.765+0000] {subprocess.py:106} INFO -     return self._wrap_pool_connect(self.pool.connect, _connection)
[2025-03-28T16:19:49.766+0000] {subprocess.py:106} INFO -            ^^^^^^^^^^^^^^^^^^^^^^^^^^^^^^^^^^^^^^^^^^^^^^^^^^^^^^^
[2025-03-28T16:19:49.766+0000] {subprocess.py:106} INFO -   File "/home/***/.local/lib/python3.12/site-packages/sqlalchemy/engine/base.py", line 3374, in _wrap_pool_connect
[2025-03-28T16:19:49.767+0000] {subprocess.py:106} INFO -     Connection._handle_dbapi_exception_noconnection(
[2025-03-28T16:19:49.767+0000] {subprocess.py:106} INFO -   File "/home/***/.local/lib/python3.12/site-packages/sqlalchemy/engine/base.py", line 2208, in _handle_dbapi_exception_noconnection
[2025-03-28T16:19:49.768+0000] {subprocess.py:106} INFO -     util.raise_(
[2025-03-28T16:19:49.769+0000] {subprocess.py:106} INFO -   File "/home/***/.local/lib/python3.12/site-packages/sqlalchemy/util/compat.py", line 211, in raise_
[2025-03-28T16:19:49.769+0000] {subprocess.py:106} INFO -     raise exception
[2025-03-28T16:19:49.770+0000] {subprocess.py:106} INFO -   File "/home/***/.local/lib/python3.12/site-packages/sqlalchemy/engine/base.py", line 3371, in _wrap_pool_connect
[2025-03-28T16:19:49.771+0000] {subprocess.py:106} INFO -     return fn()
[2025-03-28T16:19:49.771+0000] {subprocess.py:106} INFO -            ^^^^
[2025-03-28T16:19:49.772+0000] {subprocess.py:106} INFO -   File "/home/***/.local/lib/python3.12/site-packages/sqlalchemy/pool/base.py", line 327, in connect
[2025-03-28T16:19:49.773+0000] {subprocess.py:106} INFO -     return _ConnectionFairy._checkout(self)
[2025-03-28T16:19:49.773+0000] {subprocess.py:106} INFO -            ^^^^^^^^^^^^^^^^^^^^^^^^^^^^^^^^
[2025-03-28T16:19:49.774+0000] {subprocess.py:106} INFO -   File "/home/***/.local/lib/python3.12/site-packages/sqlalchemy/pool/base.py", line 894, in _checkout
[2025-03-28T16:19:49.776+0000] {subprocess.py:106} INFO -     fairy = _ConnectionRecord.checkout(pool)
[2025-03-28T16:19:49.777+0000] {subprocess.py:106} INFO -             ^^^^^^^^^^^^^^^^^^^^^^^^^^^^^^^^
[2025-03-28T16:19:49.777+0000] {subprocess.py:106} INFO -   File "/home/***/.local/lib/python3.12/site-packages/sqlalchemy/pool/base.py", line 493, in checkout
[2025-03-28T16:19:49.778+0000] {subprocess.py:106} INFO -     rec = pool._do_get()
[2025-03-28T16:19:49.779+0000] {subprocess.py:106} INFO -           ^^^^^^^^^^^^^^
[2025-03-28T16:19:49.780+0000] {subprocess.py:106} INFO -   File "/home/***/.local/lib/python3.12/site-packages/sqlalchemy/pool/impl.py", line 145, in _do_get
[2025-03-28T16:19:49.781+0000] {subprocess.py:106} INFO -     with util.safe_reraise():
[2025-03-28T16:19:49.782+0000] {subprocess.py:106} INFO -          ^^^^^^^^^^^^^^^^^^^
[2025-03-28T16:19:49.782+0000] {subprocess.py:106} INFO -   File "/home/***/.local/lib/python3.12/site-packages/sqlalchemy/util/langhelpers.py", line 70, in __exit__
[2025-03-28T16:19:49.783+0000] {subprocess.py:106} INFO -     compat.raise_(
[2025-03-28T16:19:49.784+0000] {subprocess.py:106} INFO -   File "/home/***/.local/lib/python3.12/site-packages/sqlalchemy/util/compat.py", line 211, in raise_
[2025-03-28T16:19:49.785+0000] {subprocess.py:106} INFO -     raise exception
[2025-03-28T16:19:49.785+0000] {subprocess.py:106} INFO -   File "/home/***/.local/lib/python3.12/site-packages/sqlalchemy/pool/impl.py", line 143, in _do_get
[2025-03-28T16:19:49.786+0000] {subprocess.py:106} INFO -     return self._create_connection()
[2025-03-28T16:19:49.787+0000] {subprocess.py:106} INFO -            ^^^^^^^^^^^^^^^^^^^^^^^^^
[2025-03-28T16:19:49.788+0000] {subprocess.py:106} INFO -   File "/home/***/.local/lib/python3.12/site-packages/sqlalchemy/pool/base.py", line 273, in _create_connection
[2025-03-28T16:19:49.788+0000] {subprocess.py:106} INFO -     return _ConnectionRecord(self)
[2025-03-28T16:19:49.789+0000] {subprocess.py:106} INFO -            ^^^^^^^^^^^^^^^^^^^^^^^
[2025-03-28T16:19:49.790+0000] {subprocess.py:106} INFO -   File "/home/***/.local/lib/python3.12/site-packages/sqlalchemy/pool/base.py", line 388, in __init__
[2025-03-28T16:19:49.791+0000] {subprocess.py:106} INFO -     self.__connect()
[2025-03-28T16:19:49.792+0000] {subprocess.py:106} INFO -   File "/home/***/.local/lib/python3.12/site-packages/sqlalchemy/pool/base.py", line 690, in __connect
[2025-03-28T16:19:49.793+0000] {subprocess.py:106} INFO -     with util.safe_reraise():
[2025-03-28T16:19:49.794+0000] {subprocess.py:106} INFO -          ^^^^^^^^^^^^^^^^^^^
[2025-03-28T16:19:49.795+0000] {subprocess.py:106} INFO -   File "/home/***/.local/lib/python3.12/site-packages/sqlalchemy/util/langhelpers.py", line 70, in __exit__
[2025-03-28T16:19:49.796+0000] {subprocess.py:106} INFO -     compat.raise_(
[2025-03-28T16:19:49.796+0000] {subprocess.py:106} INFO -   File "/home/***/.local/lib/python3.12/site-packages/sqlalchemy/util/compat.py", line 211, in raise_
[2025-03-28T16:19:49.799+0000] {subprocess.py:106} INFO -     raise exception
[2025-03-28T16:19:49.803+0000] {subprocess.py:106} INFO -   File "/home/***/.local/lib/python3.12/site-packages/sqlalchemy/pool/base.py", line 686, in __connect
[2025-03-28T16:19:49.817+0000] {subprocess.py:106} INFO -     self.dbapi_connection = connection = pool._invoke_creator(self)
[2025-03-28T16:19:49.818+0000] {subprocess.py:106} INFO -                                          ^^^^^^^^^^^^^^^^^^^^^^^^^^
[2025-03-28T16:19:49.819+0000] {subprocess.py:106} INFO -   File "/home/***/.local/lib/python3.12/site-packages/sqlalchemy/engine/create.py", line 574, in connect
[2025-03-28T16:19:49.820+0000] {subprocess.py:106} INFO -     return dialect.connect(*cargs, **cparams)
[2025-03-28T16:19:49.821+0000] {subprocess.py:106} INFO -            ^^^^^^^^^^^^^^^^^^^^^^^^^^^^^^^^^^
[2025-03-28T16:19:49.821+0000] {subprocess.py:106} INFO -   File "/home/***/.local/lib/python3.12/site-packages/sqlalchemy/engine/default.py", line 598, in connect
[2025-03-28T16:19:49.822+0000] {subprocess.py:106} INFO -     return self.dbapi.connect(*cargs, **cparams)
[2025-03-28T16:19:49.823+0000] {subprocess.py:106} INFO -            ^^^^^^^^^^^^^^^^^^^^^^^^^^^^^^^^^^^^^
[2025-03-28T16:19:49.823+0000] {subprocess.py:106} INFO -   File "/home/***/.local/lib/python3.12/site-packages/psycopg2/__init__.py", line 122, in connect
[2025-03-28T16:19:49.824+0000] {subprocess.py:106} INFO -     conn = _connect(dsn, connection_factory=connection_factory, **kwasync)
[2025-03-28T16:19:49.826+0000] {subprocess.py:106} INFO -            ^^^^^^^^^^^^^^^^^^^^^^^^^^^^^^^^^^^^^^^^^^^^^^^^^^^^^^^^^^^^^^^
[2025-03-28T16:19:49.827+0000] {subprocess.py:106} INFO - sqlalchemy.exc.OperationalError: (psycopg2.OperationalError) connection to server at "localhost" (::1), port 5432 failed: Connection refused
[2025-03-28T16:19:49.828+0000] {subprocess.py:106} INFO - 	Is the server running on that host and accepting TCP/IP connections?
[2025-03-28T16:19:49.829+0000] {subprocess.py:106} INFO - connection to server at "localhost" (127.0.0.1), port 5432 failed: Connection refused
[2025-03-28T16:19:49.830+0000] {subprocess.py:106} INFO - 	Is the server running on that host and accepting TCP/IP connections?
[2025-03-28T16:19:49.831+0000] {subprocess.py:106} INFO - 
[2025-03-28T16:19:49.832+0000] {subprocess.py:106} INFO - (Background on this error at: https://sqlalche.me/e/14/e3q8)
[2025-03-28T16:19:49.911+0000] {subprocess.py:110} INFO - Command exited with return code 1
[2025-03-28T16:19:49.932+0000] {taskinstance.py:3313} ERROR - Task failed with exception
Traceback (most recent call last):
  File "/home/airflow/.local/lib/python3.12/site-packages/airflow/models/taskinstance.py", line 768, in _execute_task
    result = _execute_callable(context=context, **execute_callable_kwargs)
             ^^^^^^^^^^^^^^^^^^^^^^^^^^^^^^^^^^^^^^^^^^^^^^^^^^^^^^^^^^^^^
  File "/home/airflow/.local/lib/python3.12/site-packages/airflow/models/taskinstance.py", line 734, in _execute_callable
    return ExecutionCallableRunner(
           ^^^^^^^^^^^^^^^^^^^^^^^^
  File "/home/airflow/.local/lib/python3.12/site-packages/airflow/utils/operator_helpers.py", line 252, in run
    return self.func(*args, **kwargs)
           ^^^^^^^^^^^^^^^^^^^^^^^^^^
  File "/home/airflow/.local/lib/python3.12/site-packages/airflow/models/baseoperator.py", line 424, in wrapper
    return func(self, *args, **kwargs)
           ^^^^^^^^^^^^^^^^^^^^^^^^^^^
  File "/home/airflow/.local/lib/python3.12/site-packages/airflow/operators/bash.py", line 276, in execute
    raise AirflowException(
airflow.exceptions.AirflowException: Bash command failed. The command returned a non-zero exit code 1.
[2025-03-28T16:19:49.949+0000] {logging_mixin.py:190} INFO - Task instance in failure state
[2025-03-28T16:19:49.950+0000] {logging_mixin.py:190} INFO - Task start:2025-03-28 16:19:46.604629+00:00 end:2025-03-28 16:19:49.948673+00:00 duration:3.344044
[2025-03-28T16:19:49.951+0000] {logging_mixin.py:190} INFO - Task:<Task(BashOperator): load_to_postgres> dag:<DAG: nasa_data_pipeline> dagrun:<DagRun nasa_data_pipeline @ 2025-03-28 16:19:11.887477+00:00: manual__2025-03-28T16:19:11.887477+00:00, state:running, queued_at: 2025-03-28 16:19:11.999980+00:00. externally triggered: True>
[2025-03-28T16:19:49.952+0000] {logging_mixin.py:190} INFO - Failure caused by Bash command failed. The command returned a non-zero exit code 1.
[2025-03-28T16:19:49.953+0000] {taskinstance.py:1226} INFO - Marking task as FAILED. dag_id=nasa_data_pipeline, task_id=load_to_postgres, run_id=manual__2025-03-28T16:19:11.887477+00:00, execution_date=20250328T161911, start_date=20250328T161946, end_date=20250328T161949
[2025-03-28T16:19:50.016+0000] {taskinstance.py:341} INFO - ::group::Post task execution logs
[2025-03-28T16:19:50.019+0000] {standard_task_runner.py:124} ERROR - Failed to execute job 173 for task load_to_postgres (Bash command failed. The command returned a non-zero exit code 1.; 151)
Traceback (most recent call last):
  File "/home/airflow/.local/lib/python3.12/site-packages/airflow/task/task_runner/standard_task_runner.py", line 117, in _start_by_fork
    ret = args.func(args, dag=self.dag)
          ^^^^^^^^^^^^^^^^^^^^^^^^^^^^^
  File "/home/airflow/.local/lib/python3.12/site-packages/airflow/cli/cli_config.py", line 49, in command
    return func(*args, **kwargs)
           ^^^^^^^^^^^^^^^^^^^^^
  File "/home/airflow/.local/lib/python3.12/site-packages/airflow/utils/cli.py", line 116, in wrapper
    return f(*args, **kwargs)
           ^^^^^^^^^^^^^^^^^^
  File "/home/airflow/.local/lib/python3.12/site-packages/airflow/cli/commands/task_command.py", line 483, in task_run
    task_return_code = _run_task_by_selected_method(args, _dag, ti)
                       ^^^^^^^^^^^^^^^^^^^^^^^^^^^^^^^^^^^^^^^^^^^^
  File "/home/airflow/.local/lib/python3.12/site-packages/airflow/cli/commands/task_command.py", line 256, in _run_task_by_selected_method
    return _run_raw_task(args, ti)
           ^^^^^^^^^^^^^^^^^^^^^^^
  File "/home/airflow/.local/lib/python3.12/site-packages/airflow/cli/commands/task_command.py", line 341, in _run_raw_task
    return ti._run_raw_task(
           ^^^^^^^^^^^^^^^^^
  File "/home/airflow/.local/lib/python3.12/site-packages/airflow/utils/session.py", line 97, in wrapper
    return func(*args, session=session, **kwargs)
           ^^^^^^^^^^^^^^^^^^^^^^^^^^^^^^^^^^^^^^
  File "/home/airflow/.local/lib/python3.12/site-packages/airflow/models/taskinstance.py", line 3006, in _run_raw_task
    return _run_raw_task(
           ^^^^^^^^^^^^^^
  File "/home/airflow/.local/lib/python3.12/site-packages/airflow/models/taskinstance.py", line 274, in _run_raw_task
    TaskInstance._execute_task_with_callbacks(
  File "/home/airflow/.local/lib/python3.12/site-packages/airflow/models/taskinstance.py", line 3161, in _execute_task_with_callbacks
    result = self._execute_task(context, task_orig)
             ^^^^^^^^^^^^^^^^^^^^^^^^^^^^^^^^^^^^^^
  File "/home/airflow/.local/lib/python3.12/site-packages/airflow/models/taskinstance.py", line 3185, in _execute_task
    return _execute_task(self, context, task_orig)
           ^^^^^^^^^^^^^^^^^^^^^^^^^^^^^^^^^^^^^^^
  File "/home/airflow/.local/lib/python3.12/site-packages/airflow/models/taskinstance.py", line 768, in _execute_task
    result = _execute_callable(context=context, **execute_callable_kwargs)
             ^^^^^^^^^^^^^^^^^^^^^^^^^^^^^^^^^^^^^^^^^^^^^^^^^^^^^^^^^^^^^
  File "/home/airflow/.local/lib/python3.12/site-packages/airflow/models/taskinstance.py", line 734, in _execute_callable
    return ExecutionCallableRunner(
           ^^^^^^^^^^^^^^^^^^^^^^^^
  File "/home/airflow/.local/lib/python3.12/site-packages/airflow/utils/operator_helpers.py", line 252, in run
    return self.func(*args, **kwargs)
           ^^^^^^^^^^^^^^^^^^^^^^^^^^
  File "/home/airflow/.local/lib/python3.12/site-packages/airflow/models/baseoperator.py", line 424, in wrapper
    return func(self, *args, **kwargs)
           ^^^^^^^^^^^^^^^^^^^^^^^^^^^
  File "/home/airflow/.local/lib/python3.12/site-packages/airflow/operators/bash.py", line 276, in execute
    raise AirflowException(
airflow.exceptions.AirflowException: Bash command failed. The command returned a non-zero exit code 1.
[2025-03-28T16:19:50.061+0000] {local_task_job_runner.py:266} INFO - Task exited with return code 1
[2025-03-28T16:19:50.080+0000] {taskinstance.py:3901} INFO - 0 downstream tasks scheduled from follow-on schedule check
[2025-03-28T16:19:50.085+0000] {local_task_job_runner.py:245} INFO - ::endgroup::
