[2025-03-28T16:54:03.553+0000] {local_task_job_runner.py:123} INFO - ::group::Pre task execution logs
[2025-03-28T16:54:03.580+0000] {taskinstance.py:2614} INFO - Dependencies all met for dep_context=non-requeueable deps ti=<TaskInstance: nasa_data_pipeline.load_to_postgres manual__2025-03-28T16:53:36.675677+00:00 [queued]>
[2025-03-28T16:54:03.596+0000] {taskinstance.py:2614} INFO - Dependencies all met for dep_context=requeueable deps ti=<TaskInstance: nasa_data_pipeline.load_to_postgres manual__2025-03-28T16:53:36.675677+00:00 [queued]>
[2025-03-28T16:54:03.602+0000] {taskinstance.py:2867} INFO - Starting attempt 1 of 1
[2025-03-28T16:54:03.802+0000] {taskinstance.py:2890} INFO - Executing <Task(BashOperator): load_to_postgres> on 2025-03-28 16:53:36.675677+00:00
[2025-03-28T16:54:03.815+0000] {warnings.py:112} WARNING - /home/***/.local/lib/python3.12/site-packages/***/task/task_runner/standard_task_runner.py:70: DeprecationWarning: This process (pid=591) is multi-threaded, use of fork() may lead to deadlocks in the child.
  pid = os.fork()

[2025-03-28T16:54:03.819+0000] {standard_task_runner.py:72} INFO - Started process 593 to run task
[2025-03-28T16:54:03.819+0000] {standard_task_runner.py:104} INFO - Running: ['***', 'tasks', 'run', 'nasa_data_pipeline', 'load_to_postgres', 'manual__2025-03-28T16:53:36.675677+00:00', '--job-id', '177', '--raw', '--subdir', 'DAGS_FOLDER/nasa_data_pipeline.py', '--cfg-path', '/tmp/tmpmpagqc9v']
[2025-03-28T16:54:03.821+0000] {standard_task_runner.py:105} INFO - Job 177: Subtask load_to_postgres
[2025-03-28T16:54:03.889+0000] {task_command.py:467} INFO - Running <TaskInstance: nasa_data_pipeline.load_to_postgres manual__2025-03-28T16:53:36.675677+00:00 [running]> on host 0b56b63854fa
[2025-03-28T16:54:03.978+0000] {taskinstance.py:3134} INFO - Exporting env vars: AIRFLOW_CTX_DAG_OWNER='***' AIRFLOW_CTX_DAG_ID='nasa_data_pipeline' AIRFLOW_CTX_TASK_ID='load_to_postgres' AIRFLOW_CTX_EXECUTION_DATE='2025-03-28T16:53:36.675677+00:00' AIRFLOW_CTX_TRY_NUMBER='1' AIRFLOW_CTX_DAG_RUN_ID='manual__2025-03-28T16:53:36.675677+00:00'
[2025-03-28T16:54:03.980+0000] {logging_mixin.py:190} INFO - Task instance is in running state
[2025-03-28T16:54:03.981+0000] {logging_mixin.py:190} INFO -  Previous state of the Task instance: queued
[2025-03-28T16:54:03.981+0000] {logging_mixin.py:190} INFO - Current task name:load_to_postgres state:running start_date:2025-03-28 16:54:03.581855+00:00
[2025-03-28T16:54:03.982+0000] {logging_mixin.py:190} INFO - Dag name:nasa_data_pipeline and current dag run status:running
[2025-03-28T16:54:03.983+0000] {taskinstance.py:732} INFO - ::endgroup::
[2025-03-28T16:54:03.987+0000] {subprocess.py:78} INFO - Tmp dir root location: /tmp
[2025-03-28T16:54:03.989+0000] {subprocess.py:88} INFO - Running command: ['/usr/bin/bash', '-c', 'python /opt/***/scripts/load_to_postgres.py']
[2025-03-28T16:54:04.013+0000] {subprocess.py:99} INFO - Output:
[2025-03-28T16:54:05.981+0000] {subprocess.py:106} INFO - /opt/***/scripts/load_to_postgres.py:27: RemovedIn20Warning: Deprecated API features detected! These feature(s) are not compatible with SQLAlchemy 2.0. To prevent incompatible upgrades prior to updating applications, ensure requirements files are pinned to "sqlalchemy<2.0". Set environment variable SQLALCHEMY_WARN_20=1 to show all deprecation warnings.  Set environment variable SQLALCHEMY_SILENCE_UBER_WARNING=1 to silence this message. (Background on SQLAlchemy 2.0 at: https://sqlalche.me/e/b8d9)
[2025-03-28T16:54:05.982+0000] {subprocess.py:106} INFO -   conn.execute(text(create_table_sql))
[2025-03-28T16:54:05.984+0000] {subprocess.py:106} INFO - Traceback (most recent call last):
[2025-03-28T16:54:05.986+0000] {subprocess.py:106} INFO -   File "/opt/***/scripts/load_to_postgres.py", line 31, in <module>
[2025-03-28T16:54:05.993+0000] {subprocess.py:106} INFO -     df = pd.read_csv(csv_path, dtype={"id": str})
[2025-03-28T16:54:05.994+0000] {subprocess.py:106} INFO -          ^^^^^^^^^^^^^^^^^^^^^^^^^^^^^^^^^^^^^^^^
[2025-03-28T16:54:05.995+0000] {subprocess.py:106} INFO -   File "/home/***/.local/lib/python3.12/site-packages/pandas/io/parsers/readers.py", line 948, in read_csv
[2025-03-28T16:54:05.996+0000] {subprocess.py:106} INFO -     return _read(filepath_or_buffer, kwds)
[2025-03-28T16:54:05.997+0000] {subprocess.py:106} INFO -            ^^^^^^^^^^^^^^^^^^^^^^^^^^^^^^^
[2025-03-28T16:54:05.998+0000] {subprocess.py:106} INFO -   File "/home/***/.local/lib/python3.12/site-packages/pandas/io/parsers/readers.py", line 611, in _read
[2025-03-28T16:54:05.999+0000] {subprocess.py:106} INFO -     parser = TextFileReader(filepath_or_buffer, **kwds)
[2025-03-28T16:54:06.000+0000] {subprocess.py:106} INFO -              ^^^^^^^^^^^^^^^^^^^^^^^^^^^^^^^^^^^^^^^^^^
[2025-03-28T16:54:06.001+0000] {subprocess.py:106} INFO -   File "/home/***/.local/lib/python3.12/site-packages/pandas/io/parsers/readers.py", line 1448, in __init__
[2025-03-28T16:54:06.003+0000] {subprocess.py:106} INFO -     self._engine = self._make_engine(f, self.engine)
[2025-03-28T16:54:06.004+0000] {subprocess.py:106} INFO -                    ^^^^^^^^^^^^^^^^^^^^^^^^^^^^^^^^^
[2025-03-28T16:54:06.005+0000] {subprocess.py:106} INFO -   File "/home/***/.local/lib/python3.12/site-packages/pandas/io/parsers/readers.py", line 1705, in _make_engine
[2025-03-28T16:54:06.007+0000] {subprocess.py:106} INFO -     self.handles = get_handle(
[2025-03-28T16:54:06.007+0000] {subprocess.py:106} INFO -                    ^^^^^^^^^^^
[2025-03-28T16:54:06.009+0000] {subprocess.py:106} INFO -   File "/home/***/.local/lib/python3.12/site-packages/pandas/io/common.py", line 863, in get_handle
[2025-03-28T16:54:06.010+0000] {subprocess.py:106} INFO -     handle = open(
[2025-03-28T16:54:06.011+0000] {subprocess.py:106} INFO -              ^^^^^
[2025-03-28T16:54:06.012+0000] {subprocess.py:106} INFO - FileNotFoundError: [Errno 2] No such file or directory: 'python /opt/***/scripts/load_to_postgres.py'
[2025-03-28T16:54:06.169+0000] {subprocess.py:110} INFO - Command exited with return code 1
[2025-03-28T16:54:06.185+0000] {taskinstance.py:3313} ERROR - Task failed with exception
Traceback (most recent call last):
  File "/home/airflow/.local/lib/python3.12/site-packages/airflow/models/taskinstance.py", line 768, in _execute_task
    result = _execute_callable(context=context, **execute_callable_kwargs)
             ^^^^^^^^^^^^^^^^^^^^^^^^^^^^^^^^^^^^^^^^^^^^^^^^^^^^^^^^^^^^^
  File "/home/airflow/.local/lib/python3.12/site-packages/airflow/models/taskinstance.py", line 734, in _execute_callable
    return ExecutionCallableRunner(
           ^^^^^^^^^^^^^^^^^^^^^^^^
  File "/home/airflow/.local/lib/python3.12/site-packages/airflow/utils/operator_helpers.py", line 252, in run
    return self.func(*args, **kwargs)
           ^^^^^^^^^^^^^^^^^^^^^^^^^^
  File "/home/airflow/.local/lib/python3.12/site-packages/airflow/models/baseoperator.py", line 424, in wrapper
    return func(self, *args, **kwargs)
           ^^^^^^^^^^^^^^^^^^^^^^^^^^^
  File "/home/airflow/.local/lib/python3.12/site-packages/airflow/operators/bash.py", line 276, in execute
    raise AirflowException(
airflow.exceptions.AirflowException: Bash command failed. The command returned a non-zero exit code 1.
[2025-03-28T16:54:06.192+0000] {logging_mixin.py:190} INFO - Task instance in failure state
[2025-03-28T16:54:06.193+0000] {logging_mixin.py:190} INFO - Task start:2025-03-28 16:54:03.581855+00:00 end:2025-03-28 16:54:06.191956+00:00 duration:2.610101
[2025-03-28T16:54:06.193+0000] {logging_mixin.py:190} INFO - Task:<Task(BashOperator): load_to_postgres> dag:<DAG: nasa_data_pipeline> dagrun:<DagRun nasa_data_pipeline @ 2025-03-28 16:53:36.675677+00:00: manual__2025-03-28T16:53:36.675677+00:00, state:running, queued_at: 2025-03-28 16:53:37.087243+00:00. externally triggered: True>
[2025-03-28T16:54:06.194+0000] {logging_mixin.py:190} INFO - Failure caused by Bash command failed. The command returned a non-zero exit code 1.
[2025-03-28T16:54:06.195+0000] {taskinstance.py:1226} INFO - Marking task as FAILED. dag_id=nasa_data_pipeline, task_id=load_to_postgres, run_id=manual__2025-03-28T16:53:36.675677+00:00, execution_date=20250328T165336, start_date=20250328T165403, end_date=20250328T165406
[2025-03-28T16:54:07.990+0000] {taskinstance.py:341} INFO - ::group::Post task execution logs
[2025-03-28T16:54:07.991+0000] {standard_task_runner.py:124} ERROR - Failed to execute job 177 for task load_to_postgres (Bash command failed. The command returned a non-zero exit code 1.; 593)
Traceback (most recent call last):
  File "/home/airflow/.local/lib/python3.12/site-packages/airflow/task/task_runner/standard_task_runner.py", line 117, in _start_by_fork
    ret = args.func(args, dag=self.dag)
          ^^^^^^^^^^^^^^^^^^^^^^^^^^^^^
  File "/home/airflow/.local/lib/python3.12/site-packages/airflow/cli/cli_config.py", line 49, in command
    return func(*args, **kwargs)
           ^^^^^^^^^^^^^^^^^^^^^
  File "/home/airflow/.local/lib/python3.12/site-packages/airflow/utils/cli.py", line 116, in wrapper
    return f(*args, **kwargs)
           ^^^^^^^^^^^^^^^^^^
  File "/home/airflow/.local/lib/python3.12/site-packages/airflow/cli/commands/task_command.py", line 483, in task_run
    task_return_code = _run_task_by_selected_method(args, _dag, ti)
                       ^^^^^^^^^^^^^^^^^^^^^^^^^^^^^^^^^^^^^^^^^^^^
  File "/home/airflow/.local/lib/python3.12/site-packages/airflow/cli/commands/task_command.py", line 256, in _run_task_by_selected_method
    return _run_raw_task(args, ti)
           ^^^^^^^^^^^^^^^^^^^^^^^
  File "/home/airflow/.local/lib/python3.12/site-packages/airflow/cli/commands/task_command.py", line 341, in _run_raw_task
    return ti._run_raw_task(
           ^^^^^^^^^^^^^^^^^
  File "/home/airflow/.local/lib/python3.12/site-packages/airflow/utils/session.py", line 97, in wrapper
    return func(*args, session=session, **kwargs)
           ^^^^^^^^^^^^^^^^^^^^^^^^^^^^^^^^^^^^^^
  File "/home/airflow/.local/lib/python3.12/site-packages/airflow/models/taskinstance.py", line 3006, in _run_raw_task
    return _run_raw_task(
           ^^^^^^^^^^^^^^
  File "/home/airflow/.local/lib/python3.12/site-packages/airflow/models/taskinstance.py", line 274, in _run_raw_task
    TaskInstance._execute_task_with_callbacks(
  File "/home/airflow/.local/lib/python3.12/site-packages/airflow/models/taskinstance.py", line 3161, in _execute_task_with_callbacks
    result = self._execute_task(context, task_orig)
             ^^^^^^^^^^^^^^^^^^^^^^^^^^^^^^^^^^^^^^
  File "/home/airflow/.local/lib/python3.12/site-packages/airflow/models/taskinstance.py", line 3185, in _execute_task
    return _execute_task(self, context, task_orig)
           ^^^^^^^^^^^^^^^^^^^^^^^^^^^^^^^^^^^^^^^
  File "/home/airflow/.local/lib/python3.12/site-packages/airflow/models/taskinstance.py", line 768, in _execute_task
    result = _execute_callable(context=context, **execute_callable_kwargs)
             ^^^^^^^^^^^^^^^^^^^^^^^^^^^^^^^^^^^^^^^^^^^^^^^^^^^^^^^^^^^^^
  File "/home/airflow/.local/lib/python3.12/site-packages/airflow/models/taskinstance.py", line 734, in _execute_callable
    return ExecutionCallableRunner(
           ^^^^^^^^^^^^^^^^^^^^^^^^
  File "/home/airflow/.local/lib/python3.12/site-packages/airflow/utils/operator_helpers.py", line 252, in run
    return self.func(*args, **kwargs)
           ^^^^^^^^^^^^^^^^^^^^^^^^^^
  File "/home/airflow/.local/lib/python3.12/site-packages/airflow/models/baseoperator.py", line 424, in wrapper
    return func(self, *args, **kwargs)
           ^^^^^^^^^^^^^^^^^^^^^^^^^^^
  File "/home/airflow/.local/lib/python3.12/site-packages/airflow/operators/bash.py", line 276, in execute
    raise AirflowException(
airflow.exceptions.AirflowException: Bash command failed. The command returned a non-zero exit code 1.
[2025-03-28T16:54:08.068+0000] {local_task_job_runner.py:266} INFO - Task exited with return code 1
[2025-03-28T16:54:08.103+0000] {taskinstance.py:3901} INFO - 0 downstream tasks scheduled from follow-on schedule check
[2025-03-28T16:54:08.124+0000] {local_task_job_runner.py:245} INFO - ::endgroup::
