[2025-03-28T17:19:56.283+0000] {local_task_job_runner.py:123} INFO - ::group::Pre task execution logs
[2025-03-28T17:19:56.339+0000] {taskinstance.py:2614} INFO - Dependencies all met for dep_context=non-requeueable deps ti=<TaskInstance: nasa_data_pipeline.load_to_postgres manual__2025-03-28T17:19:35.033467+00:00 [queued]>
[2025-03-28T17:19:56.379+0000] {taskinstance.py:2614} INFO - Dependencies all met for dep_context=requeueable deps ti=<TaskInstance: nasa_data_pipeline.load_to_postgres manual__2025-03-28T17:19:35.033467+00:00 [queued]>
[2025-03-28T17:19:56.397+0000] {taskinstance.py:2867} INFO - Starting attempt 1 of 1
[2025-03-28T17:19:56.600+0000] {taskinstance.py:2890} INFO - Executing <Task(BashOperator): load_to_postgres> on 2025-03-28 17:19:35.033467+00:00
[2025-03-28T17:19:56.612+0000] {warnings.py:112} WARNING - /home/***/.local/lib/python3.12/site-packages/***/task/task_runner/standard_task_runner.py:70: DeprecationWarning: This process (pid=859) is multi-threaded, use of fork() may lead to deadlocks in the child.
  pid = os.fork()

[2025-03-28T17:19:56.616+0000] {standard_task_runner.py:72} INFO - Started process 861 to run task
[2025-03-28T17:19:56.616+0000] {standard_task_runner.py:104} INFO - Running: ['***', 'tasks', 'run', 'nasa_data_pipeline', 'load_to_postgres', 'manual__2025-03-28T17:19:35.033467+00:00', '--job-id', '179', '--raw', '--subdir', 'DAGS_FOLDER/nasa_data_pipeline.py', '--cfg-path', '/tmp/tmpiiyd9m3r']
[2025-03-28T17:19:56.619+0000] {standard_task_runner.py:105} INFO - Job 179: Subtask load_to_postgres
[2025-03-28T17:19:56.692+0000] {task_command.py:467} INFO - Running <TaskInstance: nasa_data_pipeline.load_to_postgres manual__2025-03-28T17:19:35.033467+00:00 [running]> on host 0b56b63854fa
[2025-03-28T17:19:56.788+0000] {taskinstance.py:3134} INFO - Exporting env vars: AIRFLOW_CTX_DAG_OWNER='***' AIRFLOW_CTX_DAG_ID='nasa_data_pipeline' AIRFLOW_CTX_TASK_ID='load_to_postgres' AIRFLOW_CTX_EXECUTION_DATE='2025-03-28T17:19:35.033467+00:00' AIRFLOW_CTX_TRY_NUMBER='1' AIRFLOW_CTX_DAG_RUN_ID='manual__2025-03-28T17:19:35.033467+00:00'
[2025-03-28T17:19:56.792+0000] {logging_mixin.py:190} INFO - Task instance is in running state
[2025-03-28T17:19:56.793+0000] {logging_mixin.py:190} INFO -  Previous state of the Task instance: queued
[2025-03-28T17:19:56.794+0000] {logging_mixin.py:190} INFO - Current task name:load_to_postgres state:running start_date:2025-03-28 17:19:56.340268+00:00
[2025-03-28T17:19:56.795+0000] {logging_mixin.py:190} INFO - Dag name:nasa_data_pipeline and current dag run status:running
[2025-03-28T17:19:56.796+0000] {taskinstance.py:732} INFO - ::endgroup::
[2025-03-28T17:19:56.798+0000] {subprocess.py:78} INFO - Tmp dir root location: /tmp
[2025-03-28T17:19:56.803+0000] {subprocess.py:88} INFO - Running command: ['/usr/bin/bash', '-c', '/home/***/.local/bin/python3 /opt/***/scripts/load_to_postgres.py']
[2025-03-28T17:19:56.824+0000] {subprocess.py:99} INFO - Output:
[2025-03-28T17:19:59.829+0000] {subprocess.py:106} INFO - /opt/***/scripts/load_to_postgres.py:27: RemovedIn20Warning: Deprecated API features detected! These feature(s) are not compatible with SQLAlchemy 2.0. To prevent incompatible upgrades prior to updating applications, ensure requirements files are pinned to "sqlalchemy<2.0". Set environment variable SQLALCHEMY_WARN_20=1 to show all deprecation warnings.  Set environment variable SQLALCHEMY_SILENCE_UBER_WARNING=1 to silence this message. (Background on SQLAlchemy 2.0 at: https://sqlalche.me/e/b8d9)
[2025-03-28T17:19:59.835+0000] {subprocess.py:106} INFO -   conn.execute(text(create_table_sql))
[2025-03-28T17:19:59.837+0000] {subprocess.py:106} INFO - Traceback (most recent call last):
[2025-03-28T17:19:59.838+0000] {subprocess.py:106} INFO -   File "/opt/***/scripts/load_to_postgres.py", line 31, in <module>
[2025-03-28T17:19:59.842+0000] {subprocess.py:106} INFO -     df = pd.read_csv(csv_path, dtype={"id": str})
[2025-03-28T17:19:59.843+0000] {subprocess.py:106} INFO -          ^^^^^^^^^^^^^^^^^^^^^^^^^^^^^^^^^^^^^^^^
[2025-03-28T17:19:59.844+0000] {subprocess.py:106} INFO -   File "/home/***/.local/lib/python3.12/site-packages/pandas/io/parsers/readers.py", line 948, in read_csv
[2025-03-28T17:19:59.845+0000] {subprocess.py:106} INFO -     return _read(filepath_or_buffer, kwds)
[2025-03-28T17:19:59.846+0000] {subprocess.py:106} INFO -            ^^^^^^^^^^^^^^^^^^^^^^^^^^^^^^^
[2025-03-28T17:19:59.847+0000] {subprocess.py:106} INFO -   File "/home/***/.local/lib/python3.12/site-packages/pandas/io/parsers/readers.py", line 611, in _read
[2025-03-28T17:19:59.848+0000] {subprocess.py:106} INFO -     parser = TextFileReader(filepath_or_buffer, **kwds)
[2025-03-28T17:19:59.848+0000] {subprocess.py:106} INFO -              ^^^^^^^^^^^^^^^^^^^^^^^^^^^^^^^^^^^^^^^^^^
[2025-03-28T17:19:59.854+0000] {subprocess.py:106} INFO -   File "/home/***/.local/lib/python3.12/site-packages/pandas/io/parsers/readers.py", line 1448, in __init__
[2025-03-28T17:19:59.856+0000] {subprocess.py:106} INFO -     self._engine = self._make_engine(f, self.engine)
[2025-03-28T17:19:59.857+0000] {subprocess.py:106} INFO -                    ^^^^^^^^^^^^^^^^^^^^^^^^^^^^^^^^^
[2025-03-28T17:19:59.857+0000] {subprocess.py:106} INFO -   File "/home/***/.local/lib/python3.12/site-packages/pandas/io/parsers/readers.py", line 1705, in _make_engine
[2025-03-28T17:19:59.858+0000] {subprocess.py:106} INFO -     self.handles = get_handle(
[2025-03-28T17:19:59.858+0000] {subprocess.py:106} INFO -                    ^^^^^^^^^^^
[2025-03-28T17:19:59.859+0000] {subprocess.py:106} INFO -   File "/home/***/.local/lib/python3.12/site-packages/pandas/io/common.py", line 863, in get_handle
[2025-03-28T17:19:59.859+0000] {subprocess.py:106} INFO -     handle = open(
[2025-03-28T17:19:59.863+0000] {subprocess.py:106} INFO -              ^^^^^
[2025-03-28T17:19:59.865+0000] {subprocess.py:106} INFO - FileNotFoundError: [Errno 2] No such file or directory: 'python /opt/***/scripts/load_to_postgres.py'
[2025-03-28T17:20:00.290+0000] {subprocess.py:110} INFO - Command exited with return code 1
[2025-03-28T17:20:00.309+0000] {taskinstance.py:3313} ERROR - Task failed with exception
Traceback (most recent call last):
  File "/home/airflow/.local/lib/python3.12/site-packages/airflow/models/taskinstance.py", line 768, in _execute_task
    result = _execute_callable(context=context, **execute_callable_kwargs)
             ^^^^^^^^^^^^^^^^^^^^^^^^^^^^^^^^^^^^^^^^^^^^^^^^^^^^^^^^^^^^^
  File "/home/airflow/.local/lib/python3.12/site-packages/airflow/models/taskinstance.py", line 734, in _execute_callable
    return ExecutionCallableRunner(
           ^^^^^^^^^^^^^^^^^^^^^^^^
  File "/home/airflow/.local/lib/python3.12/site-packages/airflow/utils/operator_helpers.py", line 252, in run
    return self.func(*args, **kwargs)
           ^^^^^^^^^^^^^^^^^^^^^^^^^^
  File "/home/airflow/.local/lib/python3.12/site-packages/airflow/models/baseoperator.py", line 424, in wrapper
    return func(self, *args, **kwargs)
           ^^^^^^^^^^^^^^^^^^^^^^^^^^^
  File "/home/airflow/.local/lib/python3.12/site-packages/airflow/operators/bash.py", line 276, in execute
    raise AirflowException(
airflow.exceptions.AirflowException: Bash command failed. The command returned a non-zero exit code 1.
[2025-03-28T17:20:00.327+0000] {logging_mixin.py:190} INFO - Task instance in failure state
[2025-03-28T17:20:00.328+0000] {logging_mixin.py:190} INFO - Task start:2025-03-28 17:19:56.340268+00:00 end:2025-03-28 17:20:00.326453+00:00 duration:3.986185
[2025-03-28T17:20:00.329+0000] {logging_mixin.py:190} INFO - Task:<Task(BashOperator): load_to_postgres> dag:<DAG: nasa_data_pipeline> dagrun:<DagRun nasa_data_pipeline @ 2025-03-28 17:19:35.033467+00:00: manual__2025-03-28T17:19:35.033467+00:00, state:running, queued_at: 2025-03-28 17:19:35.466167+00:00. externally triggered: True>
[2025-03-28T17:20:00.331+0000] {logging_mixin.py:190} INFO - Failure caused by Bash command failed. The command returned a non-zero exit code 1.
[2025-03-28T17:20:00.333+0000] {taskinstance.py:1226} INFO - Marking task as FAILED. dag_id=nasa_data_pipeline, task_id=load_to_postgres, run_id=manual__2025-03-28T17:19:35.033467+00:00, execution_date=20250328T171935, start_date=20250328T171956, end_date=20250328T172000
[2025-03-28T17:20:00.407+0000] {taskinstance.py:341} INFO - ::group::Post task execution logs
[2025-03-28T17:20:00.409+0000] {standard_task_runner.py:124} ERROR - Failed to execute job 179 for task load_to_postgres (Bash command failed. The command returned a non-zero exit code 1.; 861)
Traceback (most recent call last):
  File "/home/airflow/.local/lib/python3.12/site-packages/airflow/task/task_runner/standard_task_runner.py", line 117, in _start_by_fork
    ret = args.func(args, dag=self.dag)
          ^^^^^^^^^^^^^^^^^^^^^^^^^^^^^
  File "/home/airflow/.local/lib/python3.12/site-packages/airflow/cli/cli_config.py", line 49, in command
    return func(*args, **kwargs)
           ^^^^^^^^^^^^^^^^^^^^^
  File "/home/airflow/.local/lib/python3.12/site-packages/airflow/utils/cli.py", line 116, in wrapper
    return f(*args, **kwargs)
           ^^^^^^^^^^^^^^^^^^
  File "/home/airflow/.local/lib/python3.12/site-packages/airflow/cli/commands/task_command.py", line 483, in task_run
    task_return_code = _run_task_by_selected_method(args, _dag, ti)
                       ^^^^^^^^^^^^^^^^^^^^^^^^^^^^^^^^^^^^^^^^^^^^
  File "/home/airflow/.local/lib/python3.12/site-packages/airflow/cli/commands/task_command.py", line 256, in _run_task_by_selected_method
    return _run_raw_task(args, ti)
           ^^^^^^^^^^^^^^^^^^^^^^^
  File "/home/airflow/.local/lib/python3.12/site-packages/airflow/cli/commands/task_command.py", line 341, in _run_raw_task
    return ti._run_raw_task(
           ^^^^^^^^^^^^^^^^^
  File "/home/airflow/.local/lib/python3.12/site-packages/airflow/utils/session.py", line 97, in wrapper
    return func(*args, session=session, **kwargs)
           ^^^^^^^^^^^^^^^^^^^^^^^^^^^^^^^^^^^^^^
  File "/home/airflow/.local/lib/python3.12/site-packages/airflow/models/taskinstance.py", line 3006, in _run_raw_task
    return _run_raw_task(
           ^^^^^^^^^^^^^^
  File "/home/airflow/.local/lib/python3.12/site-packages/airflow/models/taskinstance.py", line 274, in _run_raw_task
    TaskInstance._execute_task_with_callbacks(
  File "/home/airflow/.local/lib/python3.12/site-packages/airflow/models/taskinstance.py", line 3161, in _execute_task_with_callbacks
    result = self._execute_task(context, task_orig)
             ^^^^^^^^^^^^^^^^^^^^^^^^^^^^^^^^^^^^^^
  File "/home/airflow/.local/lib/python3.12/site-packages/airflow/models/taskinstance.py", line 3185, in _execute_task
    return _execute_task(self, context, task_orig)
           ^^^^^^^^^^^^^^^^^^^^^^^^^^^^^^^^^^^^^^^
  File "/home/airflow/.local/lib/python3.12/site-packages/airflow/models/taskinstance.py", line 768, in _execute_task
    result = _execute_callable(context=context, **execute_callable_kwargs)
             ^^^^^^^^^^^^^^^^^^^^^^^^^^^^^^^^^^^^^^^^^^^^^^^^^^^^^^^^^^^^^
  File "/home/airflow/.local/lib/python3.12/site-packages/airflow/models/taskinstance.py", line 734, in _execute_callable
    return ExecutionCallableRunner(
           ^^^^^^^^^^^^^^^^^^^^^^^^
  File "/home/airflow/.local/lib/python3.12/site-packages/airflow/utils/operator_helpers.py", line 252, in run
    return self.func(*args, **kwargs)
           ^^^^^^^^^^^^^^^^^^^^^^^^^^
  File "/home/airflow/.local/lib/python3.12/site-packages/airflow/models/baseoperator.py", line 424, in wrapper
    return func(self, *args, **kwargs)
           ^^^^^^^^^^^^^^^^^^^^^^^^^^^
  File "/home/airflow/.local/lib/python3.12/site-packages/airflow/operators/bash.py", line 276, in execute
    raise AirflowException(
airflow.exceptions.AirflowException: Bash command failed. The command returned a non-zero exit code 1.
[2025-03-28T17:20:00.467+0000] {local_task_job_runner.py:266} INFO - Task exited with return code 1
[2025-03-28T17:20:00.490+0000] {taskinstance.py:3901} INFO - 0 downstream tasks scheduled from follow-on schedule check
[2025-03-28T17:20:00.494+0000] {local_task_job_runner.py:245} INFO - ::endgroup::
